<mujoco model="pendulum">
  <include file="./common/visual.xml"/>
  <include file="./common/skybox.xml"/>
  <include file="./common/materials.xml"/>

  <!-- ðŸŽ¯ è°ƒæ•´ä»¿çœŸå‚æ•°åŒ¹é…å®žé™…æŽ§åˆ¶é¢‘çŽ‡ -->
  <option timestep="0.005" iterations="4" ls_iterations="8">
    <flag contact="disable" eulerdamp="disable"/>
  </option>

  <worldbody>
    <light name="light" pos="0 0 2"/>
    <geom name="floor" size="2 2 .2" type="plane" material="grid"/>
    <camera name="fixed" pos="0 -1.5 2" xyaxes='1 0 0 0 1 1'/>
    <camera name="lookat" mode="targetbodycom" target="pole" pos="0 -2 1"/>
    <body name="pole" pos="0 0 .4">
      <joint name="hinge" type="hinge" axis="0 1 0" 
             damping="0.08" frictionloss="0.008"/>
      
      <!-- ç”µæœºè½´ -->
      <geom name="base" material="decoration" type="cylinder" 
            fromto="0 -.03 0 0 .03 0" size="0.021" mass="0.05"/>
      
      <!-- ðŸŽ¯ è¿žæ†ï¼šé•¿åº¦0.2mï¼Œè´¨é‡0.2kg -->
      <geom name="pole" material="self" type="capsule" 
            fromto="0 0 0 0 0 -0.2" size="0.015" mass="0.2"/>
      
      <!-- ðŸŽ¯ æœ«ç«¯è´Ÿè½½ï¼š1kg -->
      <geom name="mass" material="effector" type="sphere" 
            pos="0 0 -0.2" size="0.03" mass="1.0"/>
    </body>
  </worldbody>

  <actuator>
    <motor name="torque" joint="hinge" gear="1" 
           ctrlrange="-1.2 1.2" ctrllimited="true"
           forcerange="-1.2 1.2" forcelimited="true"/>
  </actuator>

  <!-- ðŸŽ¯ å®Œæ•´çš„ä¼ æ„Ÿå™¨ç³»ç»Ÿæ¨¡æ‹ŸCANé€šä¿¡ -->
  <sensor>
    <!-- å…³èŠ‚ä½ç½®ä¼ æ„Ÿå™¨ (ç¼–ç å™¨) -->
    <jointpos name="motor_position" joint="hinge"/>
    
    <!-- å…³èŠ‚é€Ÿåº¦ä¼ æ„Ÿå™¨ -->
    <jointvel name="motor_velocity" joint="hinge"/>
    
    <!-- åŠ›çŸ©ä¼ æ„Ÿå™¨ -->
    <actuatorfrc name="motor_torque" actuator="torque"/>
  </sensor>

</mujoco>